Workbook
Name projectscount: COUNTA(Input!D10:D31)
Name Slicer_Client_Category__Sector: #N/A
Name Slicer_Location_of_Project: #N/A
Name Slicer_Month_Slicer_Column: #N/A
Name Slicer_Project_Size: #N/A
Name Slicer_Project_Type1: #N/A
Name Slicer_Risk_Index_Based_on__Commercial___Financial_Risk1: #N/A
Name Slicer_Tender_Type: #N/A

Sheet Input
C2: #VALUE! | O2: =NOW() -> 46127.533
C6: Project Profile | O6: Client & Stakeholders | S6: Competitive Position | AC6: Company Load Factor | AH6: Contractual Risk | AL6: Technical Risk | AO6: Commercial & Financial Risk
C7: Sr. No | D7: Project Name | E7: Location of Project | F7: Project Type | G7: Estimated Value | H7: Project Size | I7: Project Duration | J7: Tender Type | K7: Submission Date | L7: Year | M7: Month Slicer Column | N7: Running Month | O7: Client Name | P7: Client Category (Sector) | Q7: Consultant | R7: Project Management Consultancy (if any) | S7: Relationship Strength | T7: Budget Known | U7: Competitors | V7: Limited Invitation | W7: Similar Experience | X7: No Price Breakers (Lump-Sum) | Y7: Technical Advantage | Z7: Within Expertise | AA7: Low Changes Expected | AB7: Good Location | AC7: Team Availablility | AD7: Equipment Availablility | AE7: Cash Flow Capability | AF7: Current Workload | AG7: No Impact on Running Projects | AH7: LD (Liquidated damages) | AI7: Advance Payment Guarantee | AJ7: Performance Bond | AK7: Retention | AL7: New System (Never Done Before) | AM7: Complex MEP | AN7: Special Authority Approvals | AO7: Client Reputation | AP7: Clear Drawings | AQ7: Advance Payment | AR7: Payments | AS7: Financial Duration OK | AT7: Total Score | AU7: Risk Index Based on (Commercial & Financial Risk) | AV7: Decision Logic | AW7: Expect Win % | AX7: Hard Stop | AY7: Won, Lost & Pending | AZ7: Remarks (Reason of Won, Lost & Rejected) | BA7: Links
L8: =YEAR(Mytable[[#This Row],[Submission Date]]) -> 1900 | S8: (0-5) | T8: (0-5) | U8: (0-5) | V8: (0-5) | W8: (0-5) | X8: (0-5) | Y8: (0-5) | Z8: (0-5) | AA8: (0-5) | AB8: (0-5) | AC8: (0-5) | AD8: (0-5) | AE8: (0-5) | AF8: (0-5) | AG8: (0-5) | AH8: (0-5) | AI8: (0-5) | AJ8: (0-5) | AK8: (0-5) | AL8: (0-5) | AM8: (0-5) | AN8: (0-5) | AO8: (0-5) | AP8: (0-5) | AQ8: (0-5) | AR8: (0-5) | AS8: (0-5) | AU8: =IF(AT8<55, "HIGH", IF(AND(OR(AQ8<=2, AR8<=2), AT8<55), "HIGH", IF(AT8<90, "MEDIUM", "LOW"))) -> HIGH | AV8: =IF(AU8="HIGH", "NO GO", IF(OR(AT8>=80), "GO", IF(OR(AT8>=55, AU8="MEDIUM"), "REVIEW", "NO GO"))) -> NO GO
L9: =YEAR(Mytable[[#This Row],[Submission Date]]) -> 1900 | AU9: =IF(AT9<55, "HIGH", IF(AND(OR(AQ9<=2, AR9<=2), AT9<55), "HIGH", IF(AT9<90, "MEDIUM", "LOW"))) -> HIGH | AV9: =IF(AU9="HIGH", "NO GO", IF(OR(AT9>=80), "GO", IF(OR(AT9>=55, AU9="MEDIUM"), "REVIEW", "NO GO"))) -> NO GO
C10: {=_xlfn.SEQUENCE(COUNTA(D$10:D$1048576))} -> 1 | D10: Al Rimal | E10: Riyadh | F10: Building | G10: 1000000 | H10: =IF(G10>=3000000,"Mega",IF(G10>=2000000,"Large","Medium/Small")) -> Medium/Small | I10: 6 Months | J10: Negotiated | K10: 44562 | L10: =Mytable[[#This Row],[Submission Date]] -> 44562 | M10: January | N10: =TEXT(Mytable[[#This Row],[Submission Date]],"mmm") -> Jan | O10: 1 | P10: Gov | Q10: AECOM | R10: None | S10: 2 | T10: 5 | U10: 2 | V10: 2 | W10: 2 | X10: 2 | Y10: 2 | Z10: 2 | AA10: 2 | AB10: 5 | AC10: 2 | AD10: 4 | AE10: 0 | AF10: 0 | AG10: 1 | AH10: 2 | AI10: 2 | AJ10: 0 | AK10: 0 | AL10: 2 | AM10: 0 | AN10: 0 | AO10: 5 | AP10: 1 | AQ10: 3 | AR10: 1 | AS10: 2 | AT10: =SUM(S10:AS10) -> 51 | AU10: =IF(AT10<55, "HIGH", IF(AND(OR(AQ10<=2, AR10<=2), AT10<55), "HIGH", IF(AT10<90, "MEDIUM", "LOW"))) -> HIGH | AV10: =IF(AU10="HIGH", "NO GO", IF(OR(AT10>=80), "GO", IF(OR(AT10>=55, AU10="MEDIUM"), "REVIEW", "NO GO"))) -> NO GO | AW10: =_xlfn.LET( _xlpm.Score,AT10, _xlpm.Risk,AU10, _xlpm.Base,IF(_xlpm.Score>=101,0.75,IF(_xlpm.Score>=81,0.6,IF(_xlpm.Score>=60,0.45,IF(_xlpm.Score>=40,0.3,0.15)))), IF(_xlpm.Risk="HIGH",_xlpm.Base*0.6, IF(_xlpm.Risk="MEDIUM",_xlpm.Base*0.85,_xlpm.Base)) ) -> 0.18 | AX10: =IF(OR(Mytable[[#This Row],[Client Reputation]]=0, Mytable[[#This Row],[Clear Drawings]]=0, AQ10=0, AR10=0, AS10=0, AU10="HIGH"), "NO GO", IF(OR(AT10>=95, AU10="LOW"), "GO", IF(OR(AT10>=75, AU10="MEDIUM"), "REVIEW", "NO GO"))) -> NO GO | AY10: Rejected
C11: 2 | D11: Al Qasim | E11: Jeddah | F11: Industrial | G11: 2000000 | H11: =IF(G11>=3000000,"Mega",IF(G11>=2000000,"Large","Medium/Small")) -> Large | I11: 1 Year | J11: Limited | K11: 44563 | L11: =Mytable[[#This Row],[Submission Date]] -> 44563 | M11: February | N11: =TEXT(Mytable[[#This Row],[Submission Date]],"mmm") -> Jan | O11: 2 | P11: Gov | Q11: AECOM | R11: None | S11: 5 | T11: 5 | U11: 5 | V11: 5 | W11: 5 | X11: 5 | Y11: 5 | Z11: 5 | AA11: 5 | AB11: 5 | AC11: 5 | AD11: 5 | AE11: 5 | AF11: 5 | AG11: 5 | AH11: 5 | AI11: 5 | AJ11: 5 | AK11: 5 | AL11: 5 | AM11: 5 | AN11: 5 | AO11: 5 | AP11: 5 | AQ11: 5 | AR11: 5 | AS11: 5 | AT11: =SUM(S11:AS11) -> 135 | AU11: =IF(AT11<55, "HIGH", IF(AND(OR(AQ11<=2, AR11<=2), AT11<55), "HIGH", IF(AT11<90, "MEDIUM", "LOW"))) -> LOW | AV11: =IF(AU11="HIGH", "NO GO", IF(OR(AT11>=80), "GO", IF(OR(AT11>=55, AU11="MEDIUM"), "REVIEW", "NO GO"))) -> GO | AW11: =_xlfn.LET( _xlpm.Score,AT11, _xlpm.Risk,AU11, _xlpm.Base,IF(_xlpm.Score>=101,0.75,IF(_xlpm.Score>=81,0.6,IF(_xlpm.Score>=60,0.45,IF(_xlpm.Score>=40,0.3,0.15)))), IF(_xlpm.Risk="HIGH",_xlpm.Base*0.6, IF(_xlpm.Risk="MEDIUM",_xlpm.Base*0.85,_xlpm.Base)) ) -> 0.75 | AX11: =IF(OR(Mytable[[#This Row],[Client Reputation]]=0, Mytable[[#This Row],[Clear Drawings]]=0, AQ11=0, AR11=0, AS11=0, AU11="HIGH"), "NO GO", IF(OR(AT11>=95, AU11="LOW"), "GO", IF(OR(AT11>=75, AU11="MEDIUM"), "REVIEW", "NO GO"))) -> GO | AY11: Won
C12: 3 | D12: Riyadh | E12: Mecca (Makkah) | F12: Infrastructure | G12: 3000000 | H12: =IF(G12>=3000000,"Mega",IF(G12>=2000000,"Large","Medium/Small")) -> Mega | I12: 2 Year | J12: Open | K12: 44568 | L12: =Mytable[[#This Row],[Submission Date]] -> 44568 | M12: March | N12: =TEXT(Mytable[[#This Row],[Submission Date]],"mmm") -> Jan | O12: 3 | P12: Gov | Q12: AECOM | R12: None | S12: 4 | T12: 1 | U12: 3 | V12: 0 | W12: 1 | X12: 4 | Y12: 1 | Z12: 3 | AA12: 0 | AB12: 1 | AC12: 4 | AD12: 1 | AE12: 3 | AF12: 0 | AG12: 1 | AH12: 4 | AI12: 1 | AJ12: 3 | AK12: 0 | AL12: 1 | AM12: 3 | AN12: 0 | AO12: 5 | AP12: 3 | AQ12: 4 | AR12: 1 | AS12: 2 | AT12: =SUM(S12:AS12) -> 54 | AU12: =IF(AT12<55, "HIGH", IF(AND(OR(AQ12<=2, AR12<=2), AT12<55), "HIGH", IF(AT12<90, "MEDIUM", "LOW"))) -> HIGH | AV12: =IF(AU12="HIGH", "NO GO", IF(OR(AT12>=80), "GO", IF(OR(AT12>=55, AU12="MEDIUM"), "REVIEW", "NO GO"))) -> NO GO | AW12: =_xlfn.LET( _xlpm.Score,AT12, _xlpm.Risk,AU12, _xlpm.Base,IF(_xlpm.Score>=101,0.75,IF(_xlpm.Score>=81,0.6,IF(_xlpm.Score>=60,0.45,IF(_xlpm.Score>=40,0.3,0.15)))), IF(_xlpm.Risk="HIGH",_xlpm.Base*0.6, IF(_xlpm.Risk="MEDIUM",_xlpm.Base*0.85,_xlpm.Base)) ) -> 0.18 | AX12: =IF(OR(Mytable[[#This Row],[Client Reputation]]=0, Mytable[[#This Row],[Clear Drawings]]=0, AQ12=0, AR12=0, AS12=0, AU12="HIGH"), "NO GO", IF(OR(AT12>=95, AU12="LOW"), "GO", IF(OR(AT12>=75, AU12="MEDIUM"), "REVIEW", "NO GO"))) -> NO GO | AY12: Rejected
C13: 4 | D13: Dammam | E13: Medina (Madinah) | F13: Building | G13: 3000000 | H13: =IF(G13>=3000000,"Mega",IF(G13>=2000000,"Large","Medium/Small")) -> Mega | I13: 3 Year | J13: Open | K13: 44948 | L13: =Mytable[[#This Row],[Submission Date]] -> 44948 | M13: April | N13: =TEXT(Mytable[[#This Row],[Submission Date]],"mmm") -> Jan | O13: 4 | P13: Private | Q13: AECOM | R13: None | S13: 2 | T13: 3 | U13: 1 | V13: 0 | W13: 3 | X13: 2 | Y13: 3 | Z13: 1 | AA13: 0 | AB13: 3 | AC13: 2 | AD13: 3 | AE13: 1 | AF13: 0 | AG13: 3 | AH13: 2 | AI13: 3 | AJ13: 1 | AK13: 0 | AL13: 3 | AM13: 1 | AN13: 0 | AO13: 2 | AP13: 5 | AQ13: 5 | AR13: 3 | AS13: 0 | AT13: =SUM(S13:AS13) -> 52 | AU13: =IF(AT13<55, "HIGH", IF(AND(OR(AQ13<=2, AR13<=2), AT13<55), "HIGH", IF(AT13<90, "MEDIUM", "LOW"))) -> HIGH | AV13: =IF(AU13="HIGH", "NO GO", IF(OR(AT13>=80), "GO", IF(OR(AT13>=55, AU13="MEDIUM"), "REVIEW", "NO GO"))) -> NO GO | AW13: =_xlfn.LET( _xlpm.Score,AT13, _xlpm.Risk,AU13, _xlpm.Base,IF(_xlpm.Score>=101,0.75,IF(_xlpm.Score>=81,0.6,IF(_xlpm.Score>=60,0.45,IF(_xlpm.Score>=40,0.3,0.15)))), IF(_xlpm.Risk="HIGH",_xlpm.Base*0.6, IF(_xlpm.Risk="MEDIUM",_xlpm.Base*0.85,_xlpm.Base)) ) -> 0.18 | AX13: =IF(OR(Mytable[[#This Row],[Client Reputation]]=0, Mytable[[#This Row],[Clear Drawings]]=0, AQ13=0, AR13=0, AS13=0, AU13="HIGH"), "NO GO", IF(OR(AT13>=95, AU13="LOW"), "GO", IF(OR(AT13>=75, AU13="MEDIUM"), "REVIEW", "NO GO"))) -> NO GO | AY13: Rejected
C14: 5 | D14: Kharj | E14: Dammam | F14: Building | G14: 3000000 | H14: =IF(G14>=3000000,"Mega",IF(G14>=2000000,"Large","Medium/Small")) -> Mega | I14: 4 Year | J14: Limited | K14: 44944 | L14: =Mytable[[#This Row],[Submission Date]] -> 44944 | M14: May | N14: =TEXT(Mytable[[#This Row],[Submission Date]],"mmm") -> Jan | O14: 5 | P14: Private | Q14: AECOM | R14: None | S14: 5 | T14: 4 | U14: 4 | V14: 5 | W14: 4 | X14: 5 | Y14: 4 | Z14: 4 | AA14: 5 | AB14: 4 | AC14: 5 | AD14: 4 | AE14: 4 | AF14: 5 | AG14: 4 | AH14: 5 | AI14: 4 | AJ14: 4 | AK14: 5 | AL14: 4 | AM14: 4 | AN14: 5 | AO14: 5 | AP14: 5 | AQ14: 5 | AR14: 2 | AS14: 4 | AT14: =SUM(S14:AS14) -> 118 | AU14: =IF(AT14<55, "HIGH", IF(AND(OR(AQ14<=2, AR14<=2), AT14<55), "HIGH", IF(AT14<90, "MEDIUM", "LOW"))) -> LOW | AV14: =IF(AU14="HIGH", "NO GO", IF(OR(AT14>=80), "GO", IF(OR(AT14>=55, AU14="MEDIUM"), "REVIEW", "NO GO"))) -> GO | AW14: =_xlfn.LET( _xlpm.Score,AT14, _xlpm.Risk,AU14, _xlpm.Base,IF(_xlpm.Score>=101,0.75,IF(_xlpm.Score>=81,0.6,IF(_xlpm.Score>=60,0.45,IF(_xlpm.Score>=40,0.3,0.15)))), IF(_xlpm.Risk="HIGH",_xlpm.Base*0.6, IF(_xlpm.Risk="MEDIUM",_xlpm.Base*0.85,_xlpm.Base)) ) -> 0.75 | AX14: =IF(OR(Mytable[[#This Row],[Client Reputation]]=0, Mytable[[#This Row],[Clear Drawings]]=0, AQ14=0, AR14=0, AS14=0, AU14="HIGH"), "NO GO", IF(OR(AT14>=95, AU14="LOW"), "GO", IF(OR(AT14>=75, AU14="MEDIUM"), "REVIEW", "NO GO"))) -> GO | AY14: Pending
C15: 6 | D15: Umluj | E15: Al-Khobar | F15: Building | G15: 3000000 | H15: =IF(G15>=3000000,"Mega",IF(G15>=2000000,"Large","Medium/Small")) -> Mega | I15: 5 Year | J15: Negotiated | K15: 44957 | L15: =Mytable[[#This Row],[Submission Date]] -> 44957 | M15: June | N15: =TEXT(Mytable[[#This Row],[Submission Date]],"mmm") -> Jan | O15: 6 | P15: Gov | Q15: AECOM | R15: None | S15: 2 | T15: 3 | U15: 0 | V15: 3 | W15: 1 | X15: 2 | Y15: 3 | Z15: 0 | AA15: 3 | AB15: 1 | AC15: 2 | AD15: 3 | AE15: 0 | AF15: 3 | AG15: 1 | AH15: 2 | AI15: 3 | AJ15: 0 | AK15: 3 | AL15: 3 | AM15: 0 | AN15: 3 | AO15: 3 | AP15: 5 | AQ15: 5 | AR15: 5 | AS15: 5 | AT15: =SUM(S15:AS15) -> 64 | AU15: =IF(AT15<55, "HIGH", IF(AND(OR(AQ15<=2, AR15<=2), AT15<55), "HIGH", IF(AT15<90, "MEDIUM", "LOW"))) -> MEDIUM | AV15: =IF(AU15="HIGH", "NO GO", IF(OR(AT15>=80), "GO", IF(OR(AT15>=55, AU15="MEDIUM"), "REVIEW", "NO GO"))) -> REVIEW | AW15: =_xlfn.LET( _xlpm.Score,AT15, _xlpm.Risk,AU15, _xlpm.Base,IF(_xlpm.Score>=101,0.75,IF(_xlpm.Score>=81,0.6,IF(_xlpm.Score>=60,0.45,IF(_xlpm.Score>=40,0.3,0.15)))), IF(_xlpm.Risk="HIGH",_xlpm.Base*0.6, IF(_xlpm.Risk="MEDIUM",_xlpm.Base*0.85,_xlpm.Base)) ) -> 0.3825 | AX15: =IF(OR(Mytable[[#This Row],[Client Reputation]]=0, Mytable[[#This Row],[Clear Drawings]]=0, AQ15=0, AR15=0, AS15=0, AU15="HIGH"), "NO GO", IF(OR(AT15>=95, AU15="LOW"), "GO", IF(OR(AT15>=75, AU15="MEDIUM"), "REVIEW", "NO GO"))) -> REVIEW | AY15: Won
C16: 7 | D16: Tabuk | E16: Dhahran | F16: Industrial | G16: 3000000 | H16: =IF(G16>=3000000,"Mega",IF(G16>=2000000,"Large","Medium/Small")) -> Mega | I16: 5 Year | J16: Limited | K16: 45324 | L16: =Mytable[[#This Row],[Submission Date]] -> 45324 | M16: July | N16: =TEXT(Mytable[[#This Row],[Submission Date]],"mmm") -> Feb | O16: 7 | P16: Private | Q16: AECOM | R16: None | S16: 2 | T16: 2 | U16: 5 | V16: 2 | W16: 3 | X16: 2 | Y16: 2 | Z16: 5 | AA16: 2 | AB16: 3 | AC16: 2 | AD16: 2 | AE16: 5 | AF16: 2 | AG16: 3 | AH16: 2 | AI16: 2 | AJ16: 5 | AK16: 2 | AL16: 2 | AM16: 5 | AN16: 2 | AO16: 5 | AP16: 2 | AQ16: 5 | AR16: 4 | AS16: 2 | AT16: =SUM(S16:AS16) -> 80 | AU16: =IF(AT16<55, "HIGH", IF(AND(OR(AQ16<=2, AR16<=2), AT16<55), "HIGH", IF(AT16<90, "MEDIUM", "LOW"))) -> MEDIUM | AV16: =IF(AU16="HIGH", "NO GO", IF(OR(AT16>=80), "GO", IF(OR(AT16>=55, AU16="MEDIUM"), "REVIEW", "NO GO"))) -> GO | AW16: =_xlfn.LET( _xlpm.Score,AT16, _xlpm.Risk,AU16, _xlpm.Base,IF(_xlpm.Score>=101,0.75,IF(_xlpm.Score>=81,0.6,IF(_xlpm.Score>=60,0.45,IF(_xlpm.Score>=40,0.3,0.15)))), IF(_xlpm.Risk="HIGH",_xlpm.Base*0.6, IF(_xlpm.Risk="MEDIUM",_xlpm.Base*0.85,_xlpm.Base)) ) -> 0.3825 | AX16: =IF(OR(Mytable[[#This Row],[Client Reputation]]=0, Mytable[[#This Row],[Clear Drawings]]=0, AQ16=0, AR16=0, AS16=0, AU16="HIGH"), "NO GO", IF(OR(AT16>=95, AU16="LOW"), "GO", IF(OR(AT16>=75, AU16="MEDIUM"), "REVIEW", "NO GO"))) -> REVIEW | AY16: Won
C17: 8 | D17: Khobar | E17: Tabuk | F17: Industrial | G17: 6540000 | H17: =IF(G17>=3000000,"Mega",IF(G17>=2000000,"Large","Medium/Small")) -> Mega | I17: 5 Year | J17: Negotiated | K17: 45328 | L17: =Mytable[[#This Row],[Submission Date]] -> 45328 | M17: August | N17: =TEXT(Mytable[[#This Row],[Submission Date]],"mmm") -> Feb | O17: 8 | P17: Private | Q17: AECOM | R17: None | S17: 4 | T17: 4 | U17: 1 | V17: 0 | W17: 1 | X17: 4 | Y17: 4 | Z17: 1 | AA17: 0 | AB17: 1 | AC17: 4 | AD17: 4 | AE17: 1 | AF17: 0 | AG17: 1 | AH17: 4 | AI17: 4 | AJ17: 1 | AK17: 0 | AL17: 4 | AM17: 1 | AN17: 0 | AO17: 5 | AP17: 5 | AQ17: 1 | AR17: 5 | AS17: 2 | AT17: =SUM(S17:AS17) -> 62 | AU17: =IF(AT17<55, "HIGH", IF(AND(OR(AQ17<=2, AR17<=2), AT17<55), "HIGH", IF(AT17<90, "MEDIUM", "LOW"))) -> MEDIUM | AV17: =IF(AU17="HIGH", "NO GO", IF(OR(AT17>=80), "GO", IF(OR(AT17>=55, AU17="MEDIUM"), "REVIEW", "NO GO"))) -> REVIEW | AW17: =_xlfn.LET( _xlpm.Score,AT17, _xlpm.Risk,AU17, _xlpm.Base,IF(_xlpm.Score>=101,0.75,IF(_xlpm.Score>=81,0.6,IF(_xlpm.Score>=60,0.45,IF(_xlpm.Score>=40,0.3,0.15)))), IF(_xlpm.Risk="HIGH",_xlpm.Base*0.6, IF(_xlpm.Risk="MEDIUM",_xlpm.Base*0.85,_xlpm.Base)) ) -> 0.3825 | AX17: =IF(OR(Mytable[[#This Row],[Client Reputation]]=0, Mytable[[#This Row],[Clear Drawings]]=0, AQ17=0, AR17=0, AS17=0, AU17="HIGH"), "NO GO", IF(OR(AT17>=95, AU17="LOW"), "GO", IF(OR(AT17>=75, AU17="MEDIUM"), "REVIEW", "NO GO"))) -> REVIEW | AY17: Lost
C18: 9 | D18: Dahran | E18: Abha | F18: Industrial | G18: 800000 | H18: =IF(G18>=3000000,"Mega",IF(G18>=2000000,"Large","Medium/Small")) -> Medium/Small | I18: 5 Year | J18: Open | K18: 45332 | L18: =Mytable[[#This Row],[Submission Date]] -> 45332 | M18: September | N18: =TEXT(Mytable[[#This Row],[Submission Date]],"mmm") -> Feb | O18: 9 | P18: Gov | Q18: AECOM | R18: None | S18: 3 | T18: 3 | U18: 5 | V18: 4 | W18: 3 | X18: 3 | Y18: 3 | Z18: 5 | AA18: 4 | AB18: 3 | AC18: 3 | AD18: 3 | AE18: 5 | AF18: 4 | AG18: 3 | AH18: 5 | AI18: 5 | AJ18: 5 | AK18: 4 | AL18: 3 | AM18: 5 | AN18: 5 | AO18: 5 | AP18: 5 | AQ18: 5 | AR18: 0 | AS18: 5 | AT18: =SUM(S18:AS18) -> 106 | AU18: =IF(AT18<55, "HIGH", IF(AND(OR(AQ18<=2, AR18<=2), AT18<55), "HIGH", IF(AT18<90, "MEDIUM", "LOW"))) -> LOW | AV18: =IF(AU18="HIGH", "NO GO", IF(OR(AT18>=80), "GO", IF(OR(AT18>=55, AU18="MEDIUM"), "REVIEW", "NO GO"))) -> GO | AW18: =_xlfn.LET( _xlpm.Score,AT18, _xlpm.Risk,AU18, _xlpm.Base,IF(_xlpm.Score>=101,0.75,IF(_xlpm.Score>=81,0.6,IF(_xlpm.Score>=60,0.45,IF(_xlpm.Score>=40,0.3,0.15)))), IF(_xlpm.Risk="HIGH",_xlpm.Base*0.6, IF(_xlpm.Risk="MEDIUM",_xlpm.Base*0.85,_xlpm.Base)) ) -> 0.75 | AX18: =IF(OR(Mytable[[#This Row],[Client Reputation]]=0, Mytable[[#This Row],[Clear Drawings]]=0, AQ18=0, AR18=0, AS18=0, AU18="HIGH"), "NO GO", IF(OR(AT18>=95, AU18="LOW"), "GO", IF(OR(AT18>=75, AU18="MEDIUM"), "REVIEW", "NO GO"))) -> NO GO | AY18: Pending
C19: 10 | D19: Abha | E19: Umluj | F19: Industrial | G19: 6464000 | H19: =IF(G19>=3000000,"Mega",IF(G19>=2000000,"Large","Medium/Small")) -> Mega | I19: 5 Year | J19: Open | K19: 45344 | L19: =Mytable[[#This Row],[Submission Date]] -> 45344 | M19: October | N19: =TEXT(Mytable[[#This Row],[Submission Date]],"mmm") -> Feb | O19: 10 | P19: Semi | Q19: AECOM | R19: None | S19: 3 | T19: 1 | U19: 1 | V19: 5 | W19: 4 | X19: 3 | Y19: 1 | Z19: 1 | AA19: 5 | AB19: 4 | AC19: 3 | AD19: 1 | AE19: 1 | AF19: 5 | AG19: 4 | AH19: 3 | AI19: 1 | AJ19: 1 | AK19: 5 | AL19: 1 | AM19: 1 | AN19: 1 | AO19: 5 | AP19: 5 | AQ19: 1 | AR19: 4 | AS19: 4 | AT19: =SUM(S19:AS19) -> 74 | AU19: =IF(AT19<55, "HIGH", IF(AND(OR(AQ19<=2, AR19<=2), AT19<55), "HIGH", IF(AT19<90, "MEDIUM", "LOW"))) -> MEDIUM | AV19: =IF(AU19="HIGH", "NO GO", IF(OR(AT19>=80), "GO", IF(OR(AT19>=55, AU19="MEDIUM"), "REVIEW", "NO GO"))) -> REVIEW | AW19: =_xlfn.LET( _xlpm.Score,AT19, _xlpm.Risk,AU19, _xlpm.Base,IF(_xlpm.Score>=101,0.75,IF(_xlpm.Score>=81,0.6,IF(_xlpm.Score>=60,0.45,IF(_xlpm.Score>=40,0.3,0.15)))), IF(_xlpm.Risk="HIGH",_xlpm.Base*0.6, IF(_xlpm.Risk="MEDIUM",_xlpm.Base*0.85,_xlpm.Base)) ) -> 0.3825 | AX19: =IF(OR(Mytable[[#This Row],[Client Reputation]]=0, Mytable[[#This Row],[Clear Drawings]]=0, AQ19=0, AR19=0, AS19=0, AU19="HIGH"), "NO GO", IF(OR(AT19>=95, AU19="LOW"), "GO", IF(OR(AT19>=75, AU19="MEDIUM"), "REVIEW", "NO GO"))) -> REVIEW | AY19: Won
C20: 11 | D20: Hail | E20: Ha'il | F20: Industrial | G20: 6540000 | H20: =IF(G20>=3000000,"Mega",IF(G20>=2000000,"Large","Medium/Small")) -> Mega | I20: 5 Year | J20: Limited | K20: 45763 | L20: =Mytable[[#This Row],[Submission Date]] -> 45763 | M20: November | N20: =TEXT(Mytable[[#This Row],[Submission Date]],"mmm") -> Apr | O20: 11 | P20: Semi | Q20: AECOM | R20: None | S20: 2 | T20: 2 | U20: 4 | V20: 1 | W20: 4 | X20: 2 | Y20: 2 | Z20: 4 | AA20: 1 | AB20: 4 | AC20: 2 | AD20: 2 | AE20: 4 | AF20: 1 | AG20: 4 | AH20: 2 | AI20: 2 | AJ20: 4 | AK20: 5 | AL20: 5 | AM20: 4 | AN20: 5 | AO20: 3 | AP20: 5 | AQ20: 5 | AR20: 3 | AS20: 5 | AT20: =SUM(S20:AS20) -> 87 | AU20: =IF(AT20<55, "HIGH", IF(AND(OR(AQ20<=2, AR20<=2), AT20<55), "HIGH", IF(AT20<90, "MEDIUM", "LOW"))) -> MEDIUM | AV20: =IF(AU20="HIGH", "NO GO", IF(OR(AT20>=80), "GO", IF(OR(AT20>=55, AU20="MEDIUM"), "REVIEW", "NO GO"))) -> GO | AW20: =_xlfn.LET( _xlpm.Score,AT20, _xlpm.Risk,AU20, _xlpm.Base,IF(_xlpm.Score>=101,0.75,IF(_xlpm.Score>=81,0.6,IF(_xlpm.Score>=60,0.45,IF(_xlpm.Score>=40,0.3,0.15)))), IF(_xlpm.Risk="HIGH",_xlpm.Base*0.6, IF(_xlpm.Risk="MEDIUM",_xlpm.Base*0.85,_xlpm.Base)) ) -> 0.51 | AX20: =IF(OR(Mytable[[#This Row],[Client Reputation]]=0, Mytable[[#This Row],[Clear Drawings]]=0, AQ20=0, AR20=0, AS20=0, AU20="HIGH"), "NO GO", IF(OR(AT20>=95, AU20="LOW"), "GO", IF(OR(AT20>=75, AU20="MEDIUM"), "REVIEW", "NO GO"))) -> REVIEW | AY20: Pending
C21: 12 | D21: Ahasa | E21: Al-Ahsa (Hofuf) | F21: Building | G21: 900000 | H21: =IF(G21>=3000000,"Mega",IF(G21>=2000000,"Large","Medium/Small")) -> Medium/Small | I21: 5 Year | J21: Open | K21: 45718 | L21: =Mytable[[#This Row],[Submission Date]] -> 45718 | M21: December | N21: =TEXT(Mytable[[#This Row],[Submission Date]],"mmm") -> Mar | O21: 12 | P21: Semi | Q21: AECOM | R21: None | S21: 0 | T21: 2 | U21: 5 | V21: 2 | W21: 0 | X21: 0 | Y21: 0 | Z21: 0 | AA21: 0 | AB21: 0 | AC21: 0 | AD21: 0 | AE21: 0 | AF21: 0 | AG21: 0 | AH21: 0 | AI21: 0 | AJ21: 0 | AK21: 0 | AL21: 0 | AM21: 0 | AN21: 0 | AO21: 0 | AP21: 5 | AQ21: 5 | AR21: 4 | AS21: 2 | AT21: =SUM(S21:AS21) -> 25 | AU21: =IF(AT21<55, "HIGH", IF(AND(OR(AQ21<=2, AR21<=2), AT21<55), "HIGH", IF(AT21<90, "MEDIUM", "LOW"))) -> HIGH | AV21: =IF(AU21="HIGH", "NO GO", IF(OR(AT21>=80), "GO", IF(OR(AT21>=55, AU21="MEDIUM"), "REVIEW", "NO GO"))) -> NO GO | AW21: =_xlfn.LET( _xlpm.Score,AT21, _xlpm.Risk,AU21, _xlpm.Base,IF(_xlpm.Score>=101,0.75,IF(_xlpm.Score>=81,0.6,IF(_xlpm.Score>=60,0.45,IF(_xlpm.Score>=40,0.3,0.15)))), IF(_xlpm.Risk="HIGH",_xlpm.Base*0.6, IF(_xlpm.Risk="MEDIUM",_xlpm.Base*0.85,_xlpm.Base)) ) -> 0.09 | AX21: =IF(OR(Mytable[[#This Row],[Client Reputation]]=0, Mytable[[#This Row],[Clear Drawings]]=0, AQ21=0, AR21=0, AS21=0, AU21="HIGH"), "NO GO", IF(OR(AT21>=95, AU21="LOW"), "GO", IF(OR(AT21>=75, AU21="MEDIUM"), "REVIEW", "NO GO"))) -> NO GO | AY21: Rejected
C22: 13 | D22: Qatif | E22: Al-Qatif | F22: Building | G22: 1000000 | H22: =IF(G22>=3000000,"Mega",IF(G22>=2000000,"Large","Medium/Small")) -> Medium/Small | I22: 5 Year | J22: Open | K22: 45938 | L22: =Mytable[[#This Row],[Submission Date]] -> 45938 | N22: =TEXT(Mytable[[#This Row],[Submission Date]],"mmm") -> Oct | O22: 13 | P22: Private | Q22: AECOM | R22: None | S22: 4 | T22: 4 | U22: 1 | V22: 3 | W22: 1 | X22: 4 | Y22: 4 | Z22: 1 | AA22: 3 | AB22: 1 | AC22: 4 | AD22: 4 | AE22: 1 | AF22: 3 | AG22: 1 | AH22: 4 | AI22: 4 | AJ22: 1 | AK22: 3 | AL22: 4 | AM22: 1 | AN22: 3 | AO22: 5 | AP22: 2 | AQ22: 3 | AR22: 4 | AS22: 2 | AT22: =SUM(S22:AS22) -> 75 | AU22: =IF(AT22<55, "HIGH", IF(AND(OR(AQ22<=2, AR22<=2), AT22<55), "HIGH", IF(AT22<90, "MEDIUM", "LOW"))) -> MEDIUM | AV22: =IF(AU22="HIGH", "NO GO", IF(OR(AT22>=80), "GO", IF(OR(AT22>=55, AU22="MEDIUM"), "REVIEW", "NO GO"))) -> REVIEW | AW22: =_xlfn.LET( _xlpm.Score,AT22, _xlpm.Risk,AU22, _xlpm.Base,IF(_xlpm.Score>=101,0.75,IF(_xlpm.Score>=81,0.6,IF(_xlpm.Score>=60,0.45,IF(_xlpm.Score>=40,0.3,0.15)))), IF(_xlpm.Risk="HIGH",_xlpm.Base*0.6, IF(_xlpm.Risk="MEDIUM",_xlpm.Base*0.85,_xlpm.Base)) ) -> 0.3825 | AX22: =IF(OR(Mytable[[#This Row],[Client Reputation]]=0, Mytable[[#This Row],[Clear Drawings]]=0, AQ22=0, AR22=0, AS22=0, AU22="HIGH"), "NO GO", IF(OR(AT22>=95, AU22="LOW"), "GO", IF(OR(AT22>=75, AU22="MEDIUM"), "REVIEW", "NO GO"))) -> REVIEW | AY22: Won
C23: 14 | D23: Yanbu | E23: Yanbu | F23: Building | G23: 3000000 | H23: =IF(G23>=3000000,"Mega",IF(G23>=2000000,"Large","Medium/Small")) -> Mega | I23: 5 Year | J23: Negotiated | K23: 45973 | L23: =Mytable[[#This Row],[Submission Date]] -> 45973 | N23: =TEXT(Mytable[[#This Row],[Submission Date]],"mmm") -> Nov | O23: 14 | P23: Private | Q23: AECOM | R23: None | S23: 2 | T23: 3 | U23: 1 | V23: 0 | W23: 3 | X23: 2 | Y23: 3 | Z23: 1 | AA23: 0 | AB23: 3 | AC23: 2 | AD23: 3 | AE23: 1 | AF23: 0 | AG23: 3 | AH23: 2 | AI23: 3 | AJ23: 1 | AK23: 0 | AL23: 3 | AM23: 1 | AN23: 0 | AO23: 2 | AP23: 5 | AQ23: 5 | AR23: 3 | AS23: 1 | AT23: =SUM(S23:AS23) -> 53 | AU23: =IF(AT23<55, "HIGH", IF(AND(OR(AQ23<=2, AR23<=2), AT23<55), "HIGH", IF(AT23<90, "MEDIUM", "LOW"))) -> HIGH | AV23: =IF(AU23="HIGH", "NO GO", IF(OR(AT23>=80), "GO", IF(OR(AT23>=55, AU23="MEDIUM"), "REVIEW", "NO GO"))) -> NO GO | AW23: =_xlfn.LET( _xlpm.Score,AT23, _xlpm.Risk,AU23, _xlpm.Base,IF(_xlpm.Score>=101,0.75,IF(_xlpm.Score>=81,0.6,IF(_xlpm.Score>=60,0.45,IF(_xlpm.Score>=40,0.3,0.15)))), IF(_xlpm.Risk="HIGH",_xlpm.Base*0.6, IF(_xlpm.Risk="MEDIUM",_xlpm.Base*0.85,_xlpm.Base)) ) -> 0.18 | AX23: =IF(OR(Mytable[[#This Row],[Client Reputation]]=0, Mytable[[#This Row],[Clear Drawings]]=0, AQ23=0, AR23=0, AS23=0, AU23="HIGH"), "NO GO", IF(OR(AT23>=95, AU23="LOW"), "GO", IF(OR(AT23>=75, AU23="MEDIUM"), "REVIEW", "NO GO"))) -> NO GO | AY23: Rejected
C24: 15 | D24: Najran | E24: Najran | F24: Infrastructure | G24: 660000 | H24: =IF(G24>=3000000,"Mega",IF(G24>=2000000,"Large","Medium/Small")) -> Medium/Small | I24: 5 Year | J24: Open | K24: 46010 | L24: =Mytable[[#This Row],[Submission Date]] -> 46010 | N24: =TEXT(Mytable[[#This Row],[Submission Date]],"mmm") -> Dec | O24: 15 | P24: Semi | Q24: AECOM | R24: None | S24: 3 | T24: 3 | U24: 4 | V24: 1 | W24: 4 | X24: 3 | Y24: 3 | Z24: 4 | AA24: 1 | AB24: 4 | AC24: 3 | AD24: 3 | AE24: 4 | AF24: 1 | AG24: 4 | AH24: 3 | AI24: 3 | AJ24: 4 | AK24: 1 | AL24: 3 | AM24: 4 | AN24: 1 | AO24: 5 | AP24: 5 | AQ24: 5 | AR24: 4 | AS24: 4 | AT24: =SUM(S24:AS24) -> 87 | AU24: =IF(AT24<55, "HIGH", IF(AND(OR(AQ24<=2, AR24<=2), AT24<55), "HIGH", IF(AT24<90, "MEDIUM", "LOW"))) -> MEDIUM | AV24: =IF(AU24="HIGH", "NO GO", IF(OR(AT24>=80), "GO", IF(OR(AT24>=55, AU24="MEDIUM"), "REVIEW", "NO GO"))) -> GO | AW24: =_xlfn.LET( _xlpm.Score,AT24, _xlpm.Risk,AU24, _xlpm.Base,IF(_xlpm.Score>=101,0.75,IF(_xlpm.Score>=81,0.6,IF(_xlpm.Score>=60,0.45,IF(_xlpm.Score>=40,0.3,0.15)))), IF(_xlpm.Risk="HIGH",_xlpm.Base*0.6, IF(_xlpm.Risk="MEDIUM",_xlpm.Base*0.85,_xlpm.Base)) ) -> 0.51 | AX24: =IF(OR(Mytable[[#This Row],[Client Reputation]]=0, Mytable[[#This Row],[Clear Drawings]]=0, AQ24=0, AR24=0, AS24=0, AU24="HIGH"), "NO GO", IF(OR(AT24>=95, AU24="LOW"), "GO", IF(OR(AT24>=75, AU24="MEDIUM"), "REVIEW", "NO GO"))) -> REVIEW | AY24: Won
C25: 16 | D25: Bahah | E25: Al-Bahah | F25: Building | G25: 800000 | H25: =IF(G25>=3000000,"Mega",IF(G25>=2000000,"Large","Medium/Small")) -> Medium/Small | I25: 5 Year | J25: Open | K25: 46036 | L25: =Mytable[[#This Row],[Submission Date]] -> 46036 | N25: =TEXT(Mytable[[#This Row],[Submission Date]],"mmm") -> Jan | O25: 16 | P25: Private | Q25: AECOM | R25: None | S25: 2 | T25: 2 | U25: 4 | V25: 3 | W25: 1 | X25: 2 | Y25: 2 | Z25: 4 | AA25: 3 | AB25: 1 | AC25: 2 | AD25: 2 | AE25: 4 | AF25: 3 | AG25: 1 | AH25: 2 | AI25: 2 | AJ25: 4 | AK25: 3 | AL25: 2 | AM25: 4 | AN25: 3 | AO25: 4 | AP25: 1 | AQ25: 5 | AR25: 5 | AS25: 5 | AT25: =SUM(S25:AS25) -> 76 | AU25: =IF(AT25<55, "HIGH", IF(AND(OR(AQ25<=2, AR25<=2), AT25<55), "HIGH", IF(AT25<90, "MEDIUM", "LOW"))) -> MEDIUM | AV25: =IF(AU25="HIGH", "NO GO", IF(OR(AT25>=80), "GO", IF(OR(AT25>=55, AU25="MEDIUM"), "REVIEW", "NO GO"))) -> REVIEW | AW25: =_xlfn.LET( _xlpm.Score,AT25, _xlpm.Risk,AU25, _xlpm.Base,IF(_xlpm.Score>=101,0.75,IF(_xlpm.Score>=81,0.6,IF(_xlpm.Score>=60,0.45,IF(_xlpm.Score>=40,0.3,0.15)))), IF(_xlpm.Risk="HIGH",_xlpm.Base*0.6, IF(_xlpm.Risk="MEDIUM",_xlpm.Base*0.85,_xlpm.Base)) ) -> 0.3825 | AX25: =IF(OR(Mytable[[#This Row],[Client Reputation]]=0, Mytable[[#This Row],[Clear Drawings]]=0, AQ25=0, AR25=0, AS25=0, AU25="HIGH"), "NO GO", IF(OR(AT25>=95, AU25="LOW"), "GO", IF(OR(AT25>=75, AU25="MEDIUM"), "REVIEW", "NO GO"))) -> REVIEW | AY25: Won
C26: 17 | D26: Jizan | E26: Jazan (Jizan) | F26: Infrastructure | G26: 2000000 | H26: =IF(G26>=3000000,"Mega",IF(G26>=2000000,"Large","Medium/Small")) -> Large | I26: 5 Year | J26: Limited | K26: 46064 | L26: =Mytable[[#This Row],[Submission Date]] -> 46064 | N26: =TEXT(Mytable[[#This Row],[Submission Date]],"mmm") -> Feb | O26: 17 | P26: Private | Q26: AECOM | R26: None | S26: 5 | T26: 2 | U26: 3 | V26: 2 | W26: 3 | X26: 5 | Y26: 2 | Z26: 3 | AA26: 2 | AB26: 3 | AC26: 5 | AD26: 2 | AE26: 3 | AF26: 2 | AG26: 3 | AH26: 5 | AI26: 2 | AJ26: 3 | AK26: 2 | AL26: 2 | AM26: 3 | AN26: 2 | AO26: 5 | AP26: 5 | AQ26: 5 | AR26: 4 | AS26: 2 | AT26: =SUM(S26:AS26) -> 85 | AU26: =IF(AT26<55, "HIGH", IF(AND(OR(AQ26<=2, AR26<=2), AT26<55), "HIGH", IF(AT26<90, "MEDIUM", "LOW"))) -> MEDIUM | AV26: =IF(AU26="HIGH", "NO GO", IF(OR(AT26>=80), "GO", IF(OR(AT26>=55, AU26="MEDIUM"), "REVIEW", "NO GO"))) -> GO | AW26: =_xlfn.LET( _xlpm.Score,AT26, _xlpm.Risk,AU26, _xlpm.Base,IF(_xlpm.Score>=101,0.75,IF(_xlpm.Score>=81,0.6,IF(_xlpm.Score>=60,0.45,IF(_xlpm.Score>=40,0.3,0.15)))), IF(_xlpm.Risk="HIGH",_xlpm.Base*0.6, IF(_xlpm.Risk="MEDIUM",_xlpm.Base*0.85,_xlpm.Base)) ) -> 0.51 | AX26: =IF(OR(Mytable[[#This Row],[Client Reputation]]=0, Mytable[[#This Row],[Clear Drawings]]=0, AQ26=0, AR26=0, AS26=0, AU26="HIGH"), "NO GO", IF(OR(AT26>=95, AU26="LOW"), "GO", IF(OR(AT26>=75, AU26="MEDIUM"), "REVIEW", "NO GO"))) -> REVIEW | AY26: Won
C27: 18 | D27: Ula | E27: Al-Kharj | F27: Infrastructure | G27: 2000000 | H27: =IF(G27>=3000000,"Mega",IF(G27>=2000000,"Large","Medium/Small")) -> Large | I27: 5 Year | J27: Open | K27: 46148 | L27: =Mytable[[#This Row],[Submission Date]] -> 46148 | N27: =TEXT(Mytable[[#This Row],[Submission Date]],"mmm") -> May | O27: 18 | P27: Gov | Q27: AECOM | R27: None | S27: 4 | T27: 4 | U27: 5 | V27: 0 | W27: 1 | X27: 4 | Y27: 4 | Z27: 5 | AA27: 0 | AB27: 1 | AC27: 4 | AD27: 4 | AE27: 5 | AF27: 0 | AG27: 1 | AH27: 4 | AI27: 4 | AJ27: 5 | AK27: 0 | AL27: 4 | AM27: 5 | AN27: 0 | AO27: 5 | AP27: 5 | AQ27: 4 | AR27: 2 | AS27: 2 | AT27: =SUM(S27:AS27) -> 82 | AU27: =IF(AT27<55, "HIGH", IF(AND(OR(AQ27<=2, AR27<=2), AT27<55), "HIGH", IF(AT27<90, "MEDIUM", "LOW"))) -> MEDIUM | AV27: =IF(AU27="HIGH", "NO GO", IF(OR(AT27>=80), "GO", IF(OR(AT27>=55, AU27="MEDIUM"), "REVIEW", "NO GO"))) -> GO | AW27: =_xlfn.LET( _xlpm.Score,AT27, _xlpm.Risk,AU27, _xlpm.Base,IF(_xlpm.Score>=101,0.75,IF(_xlpm.Score>=81,0.6,IF(_xlpm.Score>=60,0.45,IF(_xlpm.Score>=40,0.3,0.15)))), IF(_xlpm.Risk="HIGH",_xlpm.Base*0.6, IF(_xlpm.Risk="MEDIUM",_xlpm.Base*0.85,_xlpm.Base)) ) -> 0.51 | AX27: =IF(OR(Mytable[[#This Row],[Client Reputation]]=0, Mytable[[#This Row],[Clear Drawings]]=0, AQ27=0, AR27=0, AS27=0, AU27="HIGH"), "NO GO", IF(OR(AT27>=95, AU27="LOW"), "GO", IF(OR(AT27>=75, AU27="MEDIUM"), "REVIEW", "NO GO"))) -> REVIEW | AY27: Lost
C28: 19 | D28: Ras Tanura | E28: Al-Ula | F28: Infrastructure | G28: 9000000 | H28: =IF(G28>=3000000,"Mega",IF(G28>=2000000,"Large","Medium/Small")) -> Mega | I28: 5 Year | J28: Negotiated | K28: 46183 | L28: =Mytable[[#This Row],[Submission Date]] -> 46183 | N28: =TEXT(Mytable[[#This Row],[Submission Date]],"mmm") -> Jun | O28: 19 | P28: Private | Q28: AECOM | R28: None | S28: 2 | T28: 3 | U28: 1 | V28: 0 | W28: 2 | X28: 2 | Y28: 3 | Z28: 1 | AA28: 0 | AB28: 2 | AC28: 2 | AD28: 3 | AE28: 1 | AF28: 0 | AG28: 2 | AH28: 2 | AI28: 3 | AJ28: 1 | AK28: 0 | AL28: 3 | AM28: 1 | AN28: 0 | AO28: 3 | AP28: 5 | AQ28: 4 | AR28: 3 | AS28: 0 | AT28: =SUM(S28:AS28) -> 49 | AU28: =IF(AT28<55, "HIGH", IF(AND(OR(AQ28<=2, AR28<=2), AT28<55), "HIGH", IF(AT28<90, "MEDIUM", "LOW"))) -> HIGH | AV28: =IF(AU28="HIGH", "NO GO", IF(OR(AT28>=80), "GO", IF(OR(AT28>=55, AU28="MEDIUM"), "REVIEW", "NO GO"))) -> NO GO | AW28: =_xlfn.LET( _xlpm.Score,AT28, _xlpm.Risk,AU28, _xlpm.Base,IF(_xlpm.Score>=101,0.75,IF(_xlpm.Score>=81,0.6,IF(_xlpm.Score>=60,0.45,IF(_xlpm.Score>=40,0.3,0.15)))), IF(_xlpm.Risk="HIGH",_xlpm.Base*0.6, IF(_xlpm.Risk="MEDIUM",_xlpm.Base*0.85,_xlpm.Base)) ) -> 0.18 | AX28: =IF(OR(Mytable[[#This Row],[Client Reputation]]=0, Mytable[[#This Row],[Clear Drawings]]=0, AQ28=0, AR28=0, AS28=0, AU28="HIGH"), "NO GO", IF(OR(AT28>=95, AU28="LOW"), "GO", IF(OR(AT28>=75, AU28="MEDIUM"), "REVIEW", "NO GO"))) -> NO GO | AY28: Rejected
C29: 20 | D29: Jubail | E29: Ras Tanura | F29: Infrastructure | G29: 8000000 | H29: =IF(G29>=3000000,"Mega",IF(G29>=2000000,"Large","Medium/Small")) -> Mega | I29: 5 Year | J29: Open | K29: 46218 | L29: =Mytable[[#This Row],[Submission Date]] -> 46218 | N29: =TEXT(Mytable[[#This Row],[Submission Date]],"mmm") -> Jul | O29: 20 | P29: Semi | Q29: AECOM | R29: None | S29: 3 | T29: 0 | U29: 1 | V29: 5 | W29: 4 | X29: 3 | Y29: 0 | Z29: 1 | AA29: 5 | AB29: 4 | AC29: 3 | AD29: 0 | AE29: 1 | AF29: 5 | AG29: 4 | AH29: 3 | AI29: 0 | AJ29: 1 | AK29: 5 | AL29: 0 | AM29: 1 | AN29: 5 | AO29: 5 | AP29: 5 | AQ29: 2 | AR29: 4 | AS29: 4 | AT29: =SUM(S29:AS29) -> 74 | AU29: =IF(AT29<55, "HIGH", IF(AND(OR(AQ29<=2, AR29<=2), AT29<55), "HIGH", IF(AT29<90, "MEDIUM", "LOW"))) -> MEDIUM | AV29: =IF(AU29="HIGH", "NO GO", IF(OR(AT29>=80), "GO", IF(OR(AT29>=55, AU29="MEDIUM"), "REVIEW", "NO GO"))) -> REVIEW | AW29: =_xlfn.LET( _xlpm.Score,AT29, _xlpm.Risk,AU29, _xlpm.Base,IF(_xlpm.Score>=101,0.75,IF(_xlpm.Score>=81,0.6,IF(_xlpm.Score>=60,0.45,IF(_xlpm.Score>=40,0.3,0.15)))), IF(_xlpm.Risk="HIGH",_xlpm.Base*0.6, IF(_xlpm.Risk="MEDIUM",_xlpm.Base*0.85,_xlpm.Base)) ) -> 0.3825 | AX29: =IF(OR(Mytable[[#This Row],[Client Reputation]]=0, Mytable[[#This Row],[Clear Drawings]]=0, AQ29=0, AR29=0, AS29=0, AU29="HIGH"), "NO GO", IF(OR(AT29>=95, AU29="LOW"), "GO", IF(OR(AT29>=75, AU29="MEDIUM"), "REVIEW", "NO GO"))) -> REVIEW | AY29: Pending
C30: 21 | D30: Hofuf | E30: Jubail | F30: Infrastructure | G30: 6500000 | H30: =IF(G30>=3000000,"Mega",IF(G30>=2000000,"Large","Medium/Small")) -> Mega | I30: 5 Year | J30: Negotiated | K30: 46246 | L30: =Mytable[[#This Row],[Submission Date]] -> 46246 | N30: =TEXT(Mytable[[#This Row],[Submission Date]],"mmm") -> Aug | O30: 21 | P30: Gov | Q30: AECOM | R30: None | S30: 3 | T30: 2 | U30: 4 | V30: 3 | W30: 3 | X30: 3 | Y30: 2 | Z30: 4 | AA30: 3 | AB30: 3 | AC30: 3 | AD30: 2 | AE30: 4 | AF30: 3 | AG30: 3 | AH30: 3 | AI30: 2 | AJ30: 4 | AK30: 3 | AL30: 2 | AM30: 4 | AN30: 3 | AO30: 5 | AP30: 4 | AQ30: 5 | AR30: 5 | AS30: 5 | AT30: =SUM(S30:AS30) -> 90 | AU30: =IF(AT30<55, "HIGH", IF(AND(OR(AQ30<=2, AR30<=2), AT30<55), "HIGH", IF(AT30<90, "MEDIUM", "LOW"))) -> LOW | AV30: =IF(AU30="HIGH", "NO GO", IF(OR(AT30>=80), "GO", IF(OR(AT30>=55, AU30="MEDIUM"), "REVIEW", "NO GO"))) -> GO | AW30: =_xlfn.LET( _xlpm.Score,AT30, _xlpm.Risk,AU30, _xlpm.Base,IF(_xlpm.Score>=101,0.75,IF(_xlpm.Score>=81,0.6,IF(_xlpm.Score>=60,0.45,IF(_xlpm.Score>=40,0.3,0.15)))), IF(_xlpm.Risk="HIGH",_xlpm.Base*0.6, IF(_xlpm.Risk="MEDIUM",_xlpm.Base*0.85,_xlpm.Base)) ) -> 0.6 | AX30: =IF(OR(Mytable[[#This Row],[Client Reputation]]=0, Mytable[[#This Row],[Clear Drawings]]=0, AQ30=0, AR30=0, AS30=0, AU30="HIGH"), "NO GO", IF(OR(AT30>=95, AU30="LOW"), "GO", IF(OR(AT30>=75, AU30="MEDIUM"), "REVIEW", "NO GO"))) -> GO | AY30: Won
C31: 22 | D31: Jeddah | E31: Al Qasim | F31: Infrastructure | G31: 3000000 | H31: =IF(G31>=3000000,"Mega",IF(G31>=2000000,"Large","Medium/Small")) -> Mega | I31: 5 Year | J31: Open | K31: 46274 | L31: =Mytable[[#This Row],[Submission Date]] -> 46274 | N31: =TEXT(Mytable[[#This Row],[Submission Date]],"mmm") -> Sep | O31: 22 | P31: Gov | Q31: AECOM | R31: None | S31: 2 | T31: 4 | U31: 5 | V31: 2 | W31: 2 | X31: 2 | Y31: 4 | Z31: 5 | AA31: 2 | AB31: 2 | AC31: 2 | AD31: 4 | AE31: 5 | AF31: 2 | AG31: 2 | AH31: 2 | AI31: 4 | AJ31: 5 | AK31: 2 | AL31: 4 | AM31: 5 | AN31: 2 | AO31: 5 | AP31: 5 | AQ31: 3 | AR31: 4 | AS31: 2 | AT31: =SUM(S31:AS31) -> 88 | AU31: =IF(AT31<55, "HIGH", IF(AND(OR(AQ31<=2, AR31<=2), AT31<55), "HIGH", IF(AT31<90, "MEDIUM", "LOW"))) -> MEDIUM | AV31: =IF(AU31="HIGH", "NO GO", IF(OR(AT31>=80), "GO", IF(OR(AT31>=55, AU31="MEDIUM"), "REVIEW", "NO GO"))) -> GO | AW31: =_xlfn.LET( _xlpm.Score,AT31, _xlpm.Risk,AU31, _xlpm.Base,IF(_xlpm.Score>=101,0.75,IF(_xlpm.Score>=81,0.6,IF(_xlpm.Score>=60,0.45,IF(_xlpm.Score>=40,0.3,0.15)))), IF(_xlpm.Risk="HIGH",_xlpm.Base*0.6, IF(_xlpm.Risk="MEDIUM",_xlpm.Base*0.85,_xlpm.Base)) ) -> 0.51 | AX31: =IF(OR(Mytable[[#This Row],[Client Reputation]]=0, Mytable[[#This Row],[Clear Drawings]]=0, AQ31=0, AR31=0, AS31=0, AU31="HIGH"), "NO GO", IF(OR(AT31>=95, AU31="LOW"), "GO", IF(OR(AT31>=75, AU31="MEDIUM"), "REVIEW", "NO GO"))) -> REVIEW | AY31: Lost

Sheet Data Processor
B2: Total No of Projects | D2: Average Win % | F2: Go Projects | H2: Review Projects | J2: High Risk Count | W2: Go Projects | X2: Risk Projects | Z2: Won Projects | AA2: Pending Projects | AB2: Lost Projects | AC2: Rejected Projects
B3: =COUNTA(Input!D10:D31) -> 22 | D3: =AVERAGEIF(Input!AW10:AW31,">0") -> 0.41215909 | F3: =COUNTIF(Input!AV10:AV31,"GO") -> 10 | H3: =COUNTIF(Input!AV10:AV31,"REVIEW") -> 6 | J3: =COUNTIFS(Input!AU10:AU31,"HIGH") -> 6 | W3: =SUMIF(Input!AV10:AV31, "Go", Input!G10:G31) -> 29500000 | X3: =SUMIF(Input!AV10:AV31, "No Go", Input!G10:G31) -> 19900000 | Z3: =SUMIF(Input!AY10:AY31, "Won", Input!G10:G31) -> 25424000 | AA3: =SUMIF(Input!AY10:AY31, "Pending", Input!G10:G31) -> 18340000 | AB3: =SUMIF(Input!AY10:AY31, "Lost", Input!G10:G31) -> 11540000 | AC3: =SUMIF(Input!AY10:AY31, "Rejected", Input!G10:G31) -> 19900000
AG6: Pie Chart
AG7: Row Labels | AH7: Count of Decision
AD8: Active Projects | AG8: GO | AH8: 0.45454545
B9: Decision Breakdown | F9: Win Probability by Client Type | I9: Risk Assessment | P9: Location Slicer | S9: Running Month Slicer | W9: Running Month Slicer | Z9: Column Chart of Contract & Estimated Value | AD9: Awaiting Projects | AG9: NO GO | AH9: 0.27272727
B10: Row Labels | C10: Count of Decision Logic | F10: Row Labels | G10: Average of Expect Win % | I10: Row Labels | J10: Count of Risk Index Based on (Commercial & Financial Risk) | P10: Row Labels | Q10: Count of Location of Project | S10: Row Labels | T10: Count of Month Slicer Column | W10: Row Labels | X10: Sum of Contract Value | Z10: Row Labels | AA10: Sum of Contract Value | AB10: Sum of Estimated Value | AD10: Row Labels | AE10: Count of Active & Awaiting Projects | AG10: REVIEW | AH10: 0.27272727
B11: GO | C11: 0.41666667 | F11: Gov | G11: 0.4485 | I11: HIGH | J11: 0.33333333 | P11: Abha | Q11: 1 | S11: January | T11: 1 | W11: Jan | X11: 800000 | Z11: Jan | AA11: 14000000 | AB11: 15800000 | AD11: Active | AE11: 11 | AG11: Grand Total | AH11: 1
B12: NO GO | C12: 0.33333333 | F12: Private | G12: 0.42375 | I12: LOW | J12: 0.25 | P12: Al-Ahsa (Hofuf) | Q12: 1 | S12: February | T12: 1 | W12: Feb | X12: 1800000 | Z12: Feb | AA12: 17444000 | AB12: 18804000 | AD12: Awaiting | AE12: 11
B13: REVIEW | C13: 0.25 | F13: Semi | G13: 0.3275 | I13: MEDIUM | J13: 0.41666667 | P13: Al-Khobar | Q13: 1 | S13: March | T13: 1 | W13: Mar | X13: 2800000 | Z13: Mar | AA13: 677000 | AB13: 900000 | AD13: Grand Total | AE13: 22
B14: Grand Total | C14: 1 | F14: Grand Total | G14: 0.41 | I14: Grand Total | J14: 1 | P14: Dammam | Q14: 1 | S14: April | T14: 1 | W14: Apr | X14: 2800000 | Z14: Apr | AA14: 6340000 | AB14: 6540000
P15: Dhahran | Q15: 1 | S15: May | T15: 1 | W15: May | X15: 2800000 | Z15: May | AA15: 1800000 | AB15: 2000000
F16: Count of Projects | P16: Ha'il | Q16: 1 | S16: June | T16: 1 | W16: Jun | X16: 2800000 | Z16: Jun | AA16: 2800000 | AB16: 9000000
F17: Row Labels | G17: Count of Project Type | H17: Row Labels | I17: Count of Project Type | P17: Jeddah | Q17: 1 | S17: July | T17: 1 | W17: Jul | X17: 2800000 | Z17: Jul | AA17: 4500000 | AB17: 8000000
F18: Building | G18: 0.36363636 | H18: Building | I18: 8 | J18: =GETPIVOTDATA("Project Type",$H$17,"Project Type","Building") -> 8 | P18: Mecca (Makkah) | Q18: 1 | S18: August | T18: 1 | W18: Aug | X18: 6340000 | Z18: Aug | AA18: 3500000 | AB18: 6500000
F19: Industrial | G19: 0.27272727 | H19: Industrial | I19: 6 | J19: =GETPIVOTDATA("Project Type",$H$17,"Project Type","Industrial") -> 6 | P19: Medina (Madinah) | Q19: 1 | S19: September | T19: 1 | W19: Sep | X19: 240000 | Z19: Sep | AA19: 2800000 | AB19: 3000000
B20: Win Probability by Location | F20: Infrastructure | G20: 0.36363636 | H20: Infrastructure | I20: 8 | J20: =GETPIVOTDATA("Project Type",$H$17,"Project Type","Infrastructure") -> 8 | P20: Riyadh | Q20: 1 | S20: October | T20: 1 | W20: Oct | X20: 6264000 | Z20: Oct | AA20: 200000 | AB20: 1000000
B21: Row Labels | C21: Sum of Expect Win % | F21: Grand Total | G21: 1 | H21: Grand Total | I21: 22 | J21: =GETPIVOTDATA("Project Type",$H$17) -> 22 | P21: Tabuk | Q21: 1 | S21: November | T21: 1 | W21: Nov | X21: 6340000 | Z21: Nov | AA21: 2800000 | AB21: 3000000
B22: Abha | C22: 0.75 | P22: Umluj | Q22: 1 | S22: December | T22: 1 | W22: Dec | X22: 677000 | Z22: Dec | AA22: 500000 | AB22: 660000
B23: Al Qasim | C23: 0.51 | F23: Guage Meter with Needle | P23: Grand Total | Q23: 12 | S23: Grand Total | T23: 12 | W23: Grand Total | X23: 36461000 | Z23: Grand Total | AA23: 57361000 | AB23: 75204000
B24: Al-Ahsa (Hofuf) | C24: 0.09 | F24: Row Labels | G24: Count of Risk Index Based on (Commercial & Financial Risk) | J24: Needle part | K24: Value | L24: RISK | M24: COUNT | N24: SCORE
B25: Al-Bahah | C25: 0.3825 | F25: HIGH | G25: 4 | H25: =F26 -> LOW | I25: 30 | J25: Pointer | K25: =N28 -> 61.25 | L25: low | M25: =G26 -> 3 | N25: 25
B26: Al-Kharj | C26: 0.51 | F26: LOW | G26: 3 | H26: =F27 -> MEDIUM | I26: 40 | J26: Needle Width | K26: 1.5 | L26: medium | M26: =G27 -> 5 | N26: 60
B27: Al-Khobar | C27: 0.3825 | F27: MEDIUM | G27: 5 | H27: =F25 -> HIGH | I27: 30 | J27: Remaining | K27: =100-K25-K26 -> 37.25 | L27: high | M27: =G25 -> 4 | N27: 90
B28: Al-Qatif | C28: 0.3825 | F28: Grand Total | G28: 12 | I28: =SUM(I25:I27) -> 100 | J28: 270o Half Pie | K28: 100 | L28: total | M28: =SUM(M25:M27) -> 12 | N28: =(M25*N25+M26*N26+M27*N27)/SUM(M25:M27) -> 61.25 | W28: Graph Chart for Won Projects | Z28: Pipeline Status | AD28: Graph chart by Month Showing Won, Lost Projects
B29: Al-Ula | C29: 0.18 | W29: Won, Lost & Pending | X29: Won | Z29: Row Labels | AA29: Count of Won, Lost, Pending | AD29: Month | AE29: Won | AF29: Lost | AG29: Pending | AH29: Rejected
B30: Dammam | C30: 0.75 | Z30: Lost | AA30: 3 | AD30: ='CEO Input'!M8 -> Jan | AE30: =COUNTIFS(CEOinput[Won, Lost, Pending],"Won",CEOinput[Running Month],AD30) -> 3 | AF30: =COUNTIFS(CEOinput[Won, Lost, Pending],"Lost",CEOinput[Running Month],AD30) -> 0 | AG30: =COUNTIFS(CEOinput[Won, Lost, Pending],"Pending",CEOinput[Running Month],AD30) -> 1 | AH30: =COUNTIFS(CEOinput[Won, Lost, Pending],"Rejected",CEOinput[Running Month],AD30) -> 3
B31: Dhahran | C31: 0.3825 | F31: Project Type Slicer | I31: Client Category Slicer | L31: Tender Type Slicer | W31: Row Labels | X31: Count of Won, Lost & Pending | Z31: Pending | AA31: 4 | AD31: ='CEO Input'!M9 -> Feb | AE31: =COUNTIFS(CEOinput[Won, Lost, Pending],"Won",CEOinput[Running Month],AD31) -> 3 | AF31: =COUNTIFS(CEOinput[Won, Lost, Pending],"Lost",CEOinput[Running Month],AD31) -> 1 | AG31: =COUNTIFS(CEOinput[Won, Lost, Pending],"Pending",CEOinput[Running Month],AD31) -> 1 | AH31: =COUNTIFS(CEOinput[Won, Lost, Pending],"Rejected",CEOinput[Running Month],AD31) -> 0
B32: Ha'il | C32: 0.51 | F32: Row Labels | G32: Count of Project Type | I32: Row Labels | J32: Count of Client Category (Sector) | L32: Row Labels | M32: Count of Tender Type | W32: 2022 | X32: 0.11111111 | Z32: Rejected | AA32: 6 | AD32: ='CEO Input'!M10 -> Mar | AE32: =COUNTIFS(CEOinput[Won, Lost, Pending],"Won",CEOinput[Running Month],AD32) -> 0 | AF32: =COUNTIFS(CEOinput[Won, Lost, Pending],"Lost",CEOinput[Running Month],AD32) -> 0 | AG32: =COUNTIFS(CEOinput[Won, Lost, Pending],"Pending",CEOinput[Running Month],AD32) -> 0 | AH32: =COUNTIFS(CEOinput[Won, Lost, Pending],"Rejected",CEOinput[Running Month],AD32) -> 1
B33: Jazan (Jizan) | C33: 0.51 | F33: Building | G33: 5 | I33: Gov | J33: 5 | L33: Limited | M33: 4 | W33: 2023 | X33: 0.11111111 | Z33: Won | AA33: 9 | AD33: ='CEO Input'!M11 -> Apr | AE33: =COUNTIFS(CEOinput[Won, Lost, Pending],"Won",CEOinput[Running Month],AD33) -> 0 | AF33: =COUNTIFS(CEOinput[Won, Lost, Pending],"Lost",CEOinput[Running Month],AD33) -> 0 | AG33: =COUNTIFS(CEOinput[Won, Lost, Pending],"Pending",CEOinput[Running Month],AD33) -> 1 | AH33: =COUNTIFS(CEOinput[Won, Lost, Pending],"Rejected",CEOinput[Running Month],AD33) -> 0
B34: Jeddah | C34: 0.75 | F34: Industrial | G34: 6 | I34: Private | J34: 4 | L34: Negotiated | M34: 3 | W34: 2024 | X34: 0.22222222 | Z34: Grand Total | AA34: 22 | AD34: ='CEO Input'!M12 -> May | AE34: =COUNTIFS(CEOinput[Won, Lost, Pending],"Won",CEOinput[Running Month],AD34) -> 0 | AF34: =COUNTIFS(CEOinput[Won, Lost, Pending],"Lost",CEOinput[Running Month],AD34) -> 1 | AG34: =COUNTIFS(CEOinput[Won, Lost, Pending],"Pending",CEOinput[Running Month],AD34) -> 0 | AH34: =COUNTIFS(CEOinput[Won, Lost, Pending],"Rejected",CEOinput[Running Month],AD34) -> 0
B35: Jubail | C35: 0.6 | F35: Infrastructure | G35: 1 | I35: Semi | J35: 3 | L35: Open | M35: 5 | W35: 2025 | X35: 0.22222222 | AD35: ='CEO Input'!M13 -> Jun | AE35: =COUNTIFS(CEOinput[Won, Lost, Pending],"Won",CEOinput[Running Month],AD35) -> 0 | AF35: =COUNTIFS(CEOinput[Won, Lost, Pending],"Lost",CEOinput[Running Month],AD35) -> 0 | AG35: =COUNTIFS(CEOinput[Won, Lost, Pending],"Pending",CEOinput[Running Month],AD35) -> 0 | AH35: =COUNTIFS(CEOinput[Won, Lost, Pending],"Rejected",CEOinput[Running Month],AD35) -> 1
B36: Mecca (Makkah) | C36: 0.18 | F36: Grand Total | G36: 12 | I36: Grand Total | J36: 12 | L36: Grand Total | M36: 12 | W36: 2026 | X36: 0.33333333 | AD36: ='CEO Input'!M14 -> Jul | AE36: =COUNTIFS(CEOinput[Won, Lost, Pending],"Won",CEOinput[Running Month],AD36) -> 0 | AF36: =COUNTIFS(CEOinput[Won, Lost, Pending],"Lost",CEOinput[Running Month],AD36) -> 0 | AG36: =COUNTIFS(CEOinput[Won, Lost, Pending],"Pending",CEOinput[Running Month],AD36) -> 1 | AH36: =COUNTIFS(CEOinput[Won, Lost, Pending],"Rejected",CEOinput[Running Month],AD36) -> 0
B37: Medina (Madinah) | C37: 0.18 | W37: Grand Total | X37: 1 | AD37: ='CEO Input'!M15 -> Aug | AE37: =COUNTIFS(CEOinput[Won, Lost, Pending],"Won",CEOinput[Running Month],AD37) -> 1 | AF37: =COUNTIFS(CEOinput[Won, Lost, Pending],"Lost",CEOinput[Running Month],AD37) -> 0 | AG37: =COUNTIFS(CEOinput[Won, Lost, Pending],"Pending",CEOinput[Running Month],AD37) -> 0 | AH37: =COUNTIFS(CEOinput[Won, Lost, Pending],"Rejected",CEOinput[Running Month],AD37) -> 0
B38: Najran | C38: 0.51 | F38: Risk Index Slicer | AD38: ='CEO Input'!M16 -> Sep | AE38: =COUNTIFS(CEOinput[Won, Lost, Pending],"Won",CEOinput[Running Month],AD38) -> 0 | AF38: =COUNTIFS(CEOinput[Won, Lost, Pending],"Lost",CEOinput[Running Month],AD38) -> 1 | AG38: =COUNTIFS(CEOinput[Won, Lost, Pending],"Pending",CEOinput[Running Month],AD38) -> 0 | AH38: =COUNTIFS(CEOinput[Won, Lost, Pending],"Rejected",CEOinput[Running Month],AD38) -> 0
B39: Ras Tanura | C39: 0.3825 | F39: Row Labels | G39: Count of Risk Index Based on (Commercial & Financial Risk) | AD39: ='CEO Input'!M17 -> Oct | AE39: =COUNTIFS(CEOinput[Won, Lost, Pending],"Won",CEOinput[Running Month],AD39) -> 1 | AF39: =COUNTIFS(CEOinput[Won, Lost, Pending],"Lost",CEOinput[Running Month],AD39) -> 0 | AG39: =COUNTIFS(CEOinput[Won, Lost, Pending],"Pending",CEOinput[Running Month],AD39) -> 0 | AH39: =COUNTIFS(CEOinput[Won, Lost, Pending],"Rejected",CEOinput[Running Month],AD39) -> 0
B40: Riyadh | C40: 0.18 | F40: HIGH | G40: 4 | AD40: ='CEO Input'!M18 -> Nov | AE40: =COUNTIFS(CEOinput[Won, Lost, Pending],"Won",CEOinput[Running Month],AD40) -> 0 | AF40: =COUNTIFS(CEOinput[Won, Lost, Pending],"Lost",CEOinput[Running Month],AD40) -> 0 | AG40: =COUNTIFS(CEOinput[Won, Lost, Pending],"Pending",CEOinput[Running Month],AD40) -> 0 | AH40: =COUNTIFS(CEOinput[Won, Lost, Pending],"Rejected",CEOinput[Running Month],AD40) -> 1
B41: Tabuk | C41: 0.3825 | F41: LOW | G41: 3 | AD41: ='CEO Input'!M19 -> Dec | AE41: =COUNTIFS(CEOinput[Won, Lost, Pending],"Won",CEOinput[Running Month],AD41) -> 1 | AF41: =COUNTIFS(CEOinput[Won, Lost, Pending],"Lost",CEOinput[Running Month],AD41) -> 0 | AG41: =COUNTIFS(CEOinput[Won, Lost, Pending],"Pending",CEOinput[Running Month],AD41) -> 0 | AH41: =COUNTIFS(CEOinput[Won, Lost, Pending],"Rejected",CEOinput[Running Month],AD41) -> 0
B42: Umluj | C42: 0.3825 | F42: MEDIUM | G42: 5 | AD42: Total | AE42: =SUM(AE30:AE41) -> 9 | AF42: =SUM(AF30:AF41) -> 3 | AG42: =SUM(AG30:AG41) -> 4 | AH42: =SUM(AH30:AH41) -> 6
B43: Yanbu | C43: 0.18 | F43: Grand Total | G43: 12
...

Sheet Dashboard Summary

Sheet CEO Input
C3: #VALUE! | N3: CEO Input Sheet
C7: =NOW() -> 46127.533 | F7: Sr. No | G7: Project Name | H7: Total Score | I7: Risk Index | J7: Decision | K7: Expected Win % | L7: Won, Lost, Pending | M7: Column1 | N7: Running Month | O7: Location of Project | P7: Contract Value | Q7: Estimated Value | R7: Actual Spend | S7: Active & Awaiting Projects
F8: {=_xlfn.SEQUENCE(COUNTA(G$8:G$1048576))} -> 1 | G8: =IF(Input!D10=0,"",Input!D10) -> Al Rimal | H8: =IF(Input!AT10=0,"",Input!AT10) -> 51 | I8: =IF(Input!AU10=0,"",Input!AU10) -> HIGH | J8: =IF(Input!AV10=0,"",Input!AV10) -> NO GO | K8: =IF(Input!AW10=0,"",Input!AW10) -> 0.18 | L8: =IF(Input!AY10=0,"",Input!AY10) -> Rejected | M8: Jan | N8: =IF(Input!N10=0,"",Input!N10) -> Jan | O8: =IF(Input!E10=0,"",Input!E10) -> Riyadh | P8: 800000 | Q8: =IF(Input!G10=0,"",Input!G10) -> 1000000 | R8: 1010000 | S8: Active
C9: Total Bids | D9: =COUNTA(Input!D10:D31) -> 22 | F9: 2 | G9: =IF(Input!D11=0,"",Input!D11) -> Al Qasim | H9: =IF(Input!AT11=0,"",Input!AT11) -> 135 | I9: =IF(Input!AU11=0,"",Input!AU11) -> LOW | J9: =IF(Input!AV11=0,"",Input!AV11) -> GO | K9: =IF(Input!AW11=0,"",Input!AW11) -> 0.75 | L9: =IF(Input!AY11=0,"",Input!AY11) -> Won | M9: Feb | N9: =IF(Input!N11=0,"",Input!N11) -> Jan | O9: =IF(Input!E11=0,"",Input!E11) -> Jeddah | P9: 1800000 | Q9: =IF(Input!G11=0,"",Input!G11) -> 2000000 | R9: 2010000 | S9: Active
C10: Won Bids | D10: =COUNTIF(CEOinput[Won, Lost, Pending],"Won") -> 9 | F10: 3 | G10: =IF(Input!D12=0,"",Input!D12) -> Riyadh | H10: =IF(Input!AT12=0,"",Input!AT12) -> 54 | I10: =IF(Input!AU12=0,"",Input!AU12) -> HIGH | J10: =IF(Input!AV12=0,"",Input!AV12) -> NO GO | K10: =IF(Input!AW12=0,"",Input!AW12) -> 0.18 | L10: =IF(Input!AY12=0,"",Input!AY12) -> Rejected | M10: Mar | N10: =IF(Input!N12=0,"",Input!N12) -> Jan | O10: =IF(Input!E12=0,"",Input!E12) -> Mecca (Makkah) | P10: 2800000 | Q10: =IF(Input!G12=0,"",Input!G12) -> 3000000 | R10: 3010000 | S10: Active
C11: Win Rate | D11: =IFERROR(D10/D9,0) -> 0.40909091 | F11: 4 | G11: =IF(Input!D13=0,"",Input!D13) -> Dammam | H11: =IF(Input!AT13=0,"",Input!AT13) -> 52 | I11: =IF(Input!AU13=0,"",Input!AU13) -> HIGH | J11: =IF(Input!AV13=0,"",Input!AV13) -> NO GO | K11: =IF(Input!AW13=0,"",Input!AW13) -> 0.18 | L11: =IF(Input!AY13=0,"",Input!AY13) -> Rejected | M11: Apr | N11: =IF(Input!N13=0,"",Input!N13) -> Jan | O11: =IF(Input!E13=0,"",Input!E13) -> Medina (Madinah) | P11: 2800000 | Q11: =IF(Input!G13=0,"",Input!G13) -> 3000000 | R11: 3010000 | S11: Awaiting
C12: Total Pipeline Value | D12: =SUM(Input!G10:G31) -> 75204000 | F12: 5 | G12: =IF(Input!D14=0,"",Input!D14) -> Kharj | H12: =IF(Input!AT14=0,"",Input!AT14) -> 118 | I12: =IF(Input!AU14=0,"",Input!AU14) -> LOW | J12: =IF(Input!AV14=0,"",Input!AV14) -> GO | K12: =IF(Input!AW14=0,"",Input!AW14) -> 0.75 | L12: =IF(Input!AY14=0,"",Input!AY14) -> Pending | M12: May | N12: =IF(Input!N14=0,"",Input!N14) -> Jan | O12: =IF(Input!E14=0,"",Input!E14) -> Dammam | P12: 2800000 | Q12: =IF(Input!G14=0,"",Input!G14) -> 3000000 | R12: 3010000 | S12: Awaiting
D13: =TEXT(D12/1000000, "0.00") & " Million SAR" -> 75.20 Million SAR | F13: 6 | G13: =IF(Input!D15=0,"",Input!D15) -> Umluj | H13: =IF(Input!AT15=0,"",Input!AT15) -> 64 | I13: =IF(Input!AU15=0,"",Input!AU15) -> MEDIUM | J13: =IF(Input!AV15=0,"",Input!AV15) -> REVIEW | K13: =IF(Input!AW15=0,"",Input!AW15) -> 0.3825 | L13: =IF(Input!AY15=0,"",Input!AY15) -> Won | M13: Jun | N13: =IF(Input!N15=0,"",Input!N15) -> Jan | O13: =IF(Input!E15=0,"",Input!E15) -> Al-Khobar | P13: 2800000 | Q13: =IF(Input!G15=0,"",Input!G15) -> 3000000 | R13: 3010000 | S13: Active
C14: Total Active Projects Pipline Value | D14: =SUMIF(CEOinput[Active & Awaiting Projects], "Active",CEOinput[Estimated Value]) -> 31740000 | F14: 7 | G14: =IF(Input!D16=0,"",Input!D16) -> Tabuk | H14: =IF(Input!AT16=0,"",Input!AT16) -> 80 | I14: =IF(Input!AU16=0,"",Input!AU16) -> MEDIUM | J14: =IF(Input!AV16=0,"",Input!AV16) -> GO | K14: =IF(Input!AW16=0,"",Input!AW16) -> 0.3825 | L14: =IF(Input!AY16=0,"",Input!AY16) -> Won | M14: Jul | N14: =IF(Input!N16=0,"",Input!N16) -> Feb | O14: =IF(Input!E16=0,"",Input!E16) -> Dhahran | P14: 2800000 | Q14: =IF(Input!G16=0,"",Input!G16) -> 3000000 | R14: 3010000 | S14: Active
D15: =TEXT(D14/1000000, "0.00") & " Million SAR" -> 31.74 Million SAR | F15: 8 | G15: =IF(Input!D17=0,"",Input!D17) -> Khobar | H15: =IF(Input!AT17=0,"",Input!AT17) -> 62 | I15: =IF(Input!AU17=0,"",Input!AU17) -> MEDIUM | J15: =IF(Input!AV17=0,"",Input!AV17) -> REVIEW | K15: =IF(Input!AW17=0,"",Input!AW17) -> 0.3825 | L15: =IF(Input!AY17=0,"",Input!AY17) -> Lost | M15: Aug | N15: =IF(Input!N17=0,"",Input!N17) -> Feb | O15: =IF(Input!E17=0,"",Input!E17) -> Tabuk | P15: 6340000 | Q15: =IF(Input!G17=0,"",Input!G17) -> 6540000 | R15: 6550000 | S15: Awaiting
F16: 9 | G16: =IF(Input!D18=0,"",Input!D18) -> Dahran | H16: =IF(Input!AT18=0,"",Input!AT18) -> 106 | I16: =IF(Input!AU18=0,"",Input!AU18) -> LOW | J16: =IF(Input!AV18=0,"",Input!AV18) -> GO | K16: =IF(Input!AW18=0,"",Input!AW18) -> 0.75 | L16: =IF(Input!AY18=0,"",Input!AY18) -> Pending | M16: Sep | N16: =IF(Input!N18=0,"",Input!N18) -> Feb | O16: =IF(Input!E18=0,"",Input!E18) -> Abha | P16: 240000 | Q16: =IF(Input!G18=0,"",Input!G18) -> 800000 | R16: 450000 | S16: Awaiting
F17: 10 | G17: =IF(Input!D19=0,"",Input!D19) -> Abha | H17: =IF(Input!AT19=0,"",Input!AT19) -> 74 | I17: =IF(Input!AU19=0,"",Input!AU19) -> MEDIUM | J17: =IF(Input!AV19=0,"",Input!AV19) -> REVIEW | K17: =IF(Input!AW19=0,"",Input!AW19) -> 0.3825 | L17: =IF(Input!AY19=0,"",Input!AY19) -> Won | M17: Oct | N17: =IF(Input!N19=0,"",Input!N19) -> Feb | O17: =IF(Input!E19=0,"",Input!E19) -> Umluj | P17: 6264000 | Q17: =IF(Input!G19=0,"",Input!G19) -> 6464000 | R17: 6465000 | S17: Awaiting
F18: 11 | G18: =IF(Input!D20=0,"",Input!D20) -> Hail | H18: =IF(Input!AT20=0,"",Input!AT20) -> 87 | I18: =IF(Input!AU20=0,"",Input!AU20) -> MEDIUM | J18: =IF(Input!AV20=0,"",Input!AV20) -> GO | K18: =IF(Input!AW20=0,"",Input!AW20) -> 0.51 | L18: =IF(Input!AY20=0,"",Input!AY20) -> Pending | M18: Nov | N18: =IF(Input!N20=0,"",Input!N20) -> Apr | O18: =IF(Input!E20=0,"",Input!E20) -> Ha'il | P18: 6340000 | Q18: =IF(Input!G20=0,"",Input!G20) -> 6540000 | R18: 6550000 | S18: Active
F19: 12 | G19: =IF(Input!D21=0,"",Input!D21) -> Ahasa | H19: =IF(Input!AT21=0,"",Input!AT21) -> 25 | I19: =IF(Input!AU21=0,"",Input!AU21) -> HIGH | J19: =IF(Input!AV21=0,"",Input!AV21) -> NO GO | K19: =IF(Input!AW21=0,"",Input!AW21) -> 0.09 | L19: =IF(Input!AY21=0,"",Input!AY21) -> Rejected | M19: Dec | N19: =IF(Input!N21=0,"",Input!N21) -> Mar | O19: =IF(Input!E21=0,"",Input!E21) -> Al-Ahsa (Hofuf) | P19: 677000 | Q19: =IF(Input!G21=0,"",Input!G21) -> 900000 | R19: 780000 | S19: Active
F20: 13 | G20: =IF(Input!D22=0,"",Input!D22) -> Qatif | H20: =IF(Input!AT22=0,"",Input!AT22) -> 75 | I20: =IF(Input!AU22=0,"",Input!AU22) -> MEDIUM | J20: =IF(Input!AV22=0,"",Input!AV22) -> REVIEW | K20: =IF(Input!AW22=0,"",Input!AW22) -> 0.3825 | L20: =IF(Input!AY22=0,"",Input!AY22) -> Won | N20: =IF(Input!N22=0,"",Input!N22) -> Oct | O20: =IF(Input!E22=0,"",Input!E22) -> Al-Qatif | P20: 200000 | Q20: =IF(Input!G22=0,"",Input!G22) -> 1000000 | R20: 1010000 | S20: Awaiting
F21: 14 | G21: =IF(Input!D23=0,"",Input!D23) -> Yanbu | H21: =IF(Input!AT23=0,"",Input!AT23) -> 53 | I21: =IF(Input!AU23=0,"",Input!AU23) -> HIGH | J21: =IF(Input!AV23=0,"",Input!AV23) -> NO GO | K21: =IF(Input!AW23=0,"",Input!AW23) -> 0.18 | L21: =IF(Input!AY23=0,"",Input!AY23) -> Rejected | N21: =IF(Input!N23=0,"",Input!N23) -> Nov | O21: =IF(Input!E23=0,"",Input!E23) -> Yanbu | P21: 2800000 | Q21: =IF(Input!G23=0,"",Input!G23) -> 3000000 | R21: 3010000 | S21: Awaiting
F22: 15 | G22: =IF(Input!D24=0,"",Input!D24) -> Najran | H22: =IF(Input!AT24=0,"",Input!AT24) -> 87 | I22: =IF(Input!AU24=0,"",Input!AU24) -> MEDIUM | J22: =IF(Input!AV24=0,"",Input!AV24) -> GO | K22: =IF(Input!AW24=0,"",Input!AW24) -> 0.51 | L22: =IF(Input!AY24=0,"",Input!AY24) -> Won | N22: =IF(Input!N24=0,"",Input!N24) -> Dec | O22: =IF(Input!E24=0,"",Input!E24) -> Najran | P22: 500000 | Q22: =IF(Input!G24=0,"",Input!G24) -> 660000 | R22: 670000 | S22: Awaiting
F23: 16 | G23: =IF(Input!D25=0,"",Input!D25) -> Bahah | H23: =IF(Input!AT25=0,"",Input!AT25) -> 76 | I23: =IF(Input!AU25=0,"",Input!AU25) -> MEDIUM | J23: =IF(Input!AV25=0,"",Input!AV25) -> REVIEW | K23: =IF(Input!AW25=0,"",Input!AW25) -> 0.3825 | L23: =IF(Input!AY25=0,"",Input!AY25) -> Won | N23: =IF(Input!N25=0,"",Input!N25) -> Jan | O23: =IF(Input!E25=0,"",Input!E25) -> Al-Bahah | P23: 200000 | Q23: =IF(Input!G25=0,"",Input!G25) -> 800000 | R23: 210000 | S23: Active
F24: 17 | G24: =IF(Input!D26=0,"",Input!D26) -> Jizan | H24: =IF(Input!AT26=0,"",Input!AT26) -> 85 | I24: =IF(Input!AU26=0,"",Input!AU26) -> MEDIUM | J24: =IF(Input!AV26=0,"",Input!AV26) -> GO | K24: =IF(Input!AW26=0,"",Input!AW26) -> 0.51 | L24: =IF(Input!AY26=0,"",Input!AY26) -> Won | N24: =IF(Input!N26=0,"",Input!N26) -> Feb | O24: =IF(Input!E26=0,"",Input!E26) -> Jazan (Jizan) | P24: 1800000 | Q24: =IF(Input!G26=0,"",Input!G26) -> 2000000 | R24: 2010000 | S24: Active
F25: 18 | G25: =IF(Input!D27=0,"",Input!D27) -> Ula | H25: =IF(Input!AT27=0,"",Input!AT27) -> 82 | I25: =IF(Input!AU27=0,"",Input!AU27) -> MEDIUM | J25: =IF(Input!AV27=0,"",Input!AV27) -> GO | K25: =IF(Input!AW27=0,"",Input!AW27) -> 0.51 | L25: =IF(Input!AY27=0,"",Input!AY27) -> Lost | N25: =IF(Input!N27=0,"",Input!N27) -> May | O25: =IF(Input!E27=0,"",Input!E27) -> Al-Kharj | P25: 1800000 | Q25: =IF(Input!G27=0,"",Input!G27) -> 2000000 | R25: 2010000 | S25: Awaiting
F26: 19 | G26: =IF(Input!D28=0,"",Input!D28) -> Ras Tanura | H26: =IF(Input!AT28=0,"",Input!AT28) -> 49 | I26: =IF(Input!AU28=0,"",Input!AU28) -> HIGH | J26: =IF(Input!AV28=0,"",Input!AV28) -> NO GO | K26: =IF(Input!AW28=0,"",Input!AW28) -> 0.18 | L26: =IF(Input!AY28=0,"",Input!AY28) -> Rejected | N26: =IF(Input!N28=0,"",Input!N28) -> Jun | O26: =IF(Input!E28=0,"",Input!E28) -> Al-Ula | P26: 2800000 | Q26: =IF(Input!G28=0,"",Input!G28) -> 9000000 | R26: 3010000 | S26: Awaiting
F27: 20 | G27: =IF(Input!D29=0,"",Input!D29) -> Jubail | H27: =IF(Input!AT29=0,"",Input!AT29) -> 74 | I27: =IF(Input!AU29=0,"",Input!AU29) -> MEDIUM | J27: =IF(Input!AV29=0,"",Input!AV29) -> REVIEW | K27: =IF(Input!AW29=0,"",Input!AW29) -> 0.3825 | L27: =IF(Input!AY29=0,"",Input!AY29) -> Pending | N27: =IF(Input!N29=0,"",Input!N29) -> Jul | O27: =IF(Input!E29=0,"",Input!E29) -> Ras Tanura | P27: 4500000 | Q27: =IF(Input!G29=0,"",Input!G29) -> 8000000 | R27: 3010000 | S27: Awaiting
F28: 21 | G28: =IF(Input!D30=0,"",Input!D30) -> Hofuf | H28: =IF(Input!AT30=0,"",Input!AT30) -> 90 | I28: =IF(Input!AU30=0,"",Input!AU30) -> LOW | J28: =IF(Input!AV30=0,"",Input!AV30) -> GO | K28: =IF(Input!AW30=0,"",Input!AW30) -> 0.6 | L28: =IF(Input!AY30=0,"",Input!AY30) -> Won | N28: =IF(Input!N30=0,"",Input!N30) -> Aug | O28: =IF(Input!E30=0,"",Input!E30) -> Jubail | P28: 3500000 | Q28: =IF(Input!G30=0,"",Input!G30) -> 6500000 | R28: 3010000 | S28: Active
F29: 22 | G29: =IF(Input!D31=0,"",Input!D31) -> Jeddah | H29: =IF(Input!AT31=0,"",Input!AT31) -> 88 | I29: =IF(Input!AU31=0,"",Input!AU31) -> MEDIUM | J29: =IF(Input!AV31=0,"",Input!AV31) -> GO | K29: =IF(Input!AW31=0,"",Input!AW31) -> 0.51 | L29: =IF(Input!AY31=0,"",Input!AY31) -> Lost | N29: =IF(Input!N31=0,"",Input!N31) -> Sep | O29: =IF(Input!E31=0,"",Input!E31) -> Al Qasim | P29: 2800000 | Q29: =IF(Input!G31=0,"",Input!G31) -> 3000000 | R29: 3010000 | S29: Active
H30: =IF(Input!AT32=0,"",Input!AT32) | I30: =IF(Input!AU32=0,"",Input!AU32) | J30: =IF(Input!AV32=0,"",Input!AV32) | K30: =IF(Input!AW32=0,"",Input!AW32) | L30: =IF(Input!AY32=0,"",Input!AY32) | N30: =IF(Input!N32=0,"",Input!N32) | O30: =IF(Input!E32=0,"",Input!E32) | Q30: =IF(Input!G32=0,"",Input!G32)
H31: =IF(Input!AT33=0,"",Input!AT33) | I31: =IF(Input!AU33=0,"",Input!AU33) | J31: =IF(Input!AV33=0,"",Input!AV33) | K31: =IF(Input!AW33=0,"",Input!AW33) | L31: =IF(Input!AY33=0,"",Input!AY33) | N31: =IF(Input!N33=0,"",Input!N33) | O31: =IF(Input!E33=0,"",Input!E33) | Q31: =IF(Input!G33=0,"",Input!G33)
H32: =IF(Input!AT34=0,"",Input!AT34) | I32: =IF(Input!AU34=0,"",Input!AU34) | J32: =IF(Input!AV34=0,"",Input!AV34) | K32: =IF(Input!AW34=0,"",Input!AW34) | L32: =IF(Input!AY34=0,"",Input!AY34) | N32: =IF(Input!N34=0,"",Input!N34) | O32: =IF(Input!E34=0,"",Input!E34) | Q32: =IF(Input!G34=0,"",Input!G34)
H33: =IF(Input!AT32=0,"",Input!AT32) | I33: =IF(Input!AU32=0,"",Input!AU32) | J33: =IF(Input!AV32=0,"",Input!AV32) | K33: =IF(Input!AW32=0,"",Input!AW32) | N33: =IF(Input!N32=0,"",Input!N32) | O33: =IF(Input!E32=0,"",Input!E32)
H34: =IF(Input!AT33=0,"",Input!AT33) | I34: =IF(Input!AU33=0,"",Input!AU33) | J34: =IF(Input!AV33=0,"",Input!AV33) | K34: =IF(Input!AW33=0,"",Input!AW33) | N34: =IF(Input!N33=0,"",Input!N33) | O34: =IF(Input!E33=0,"",Input!E33)
H35: =IF(Input!AT34=0,"",Input!AT34) | I35: =IF(Input!AU34=0,"",Input!AU34) | J35: =IF(Input!AV34=0,"",Input!AV34) | K35: =IF(Input!AW34=0,"",Input!AW34) | N35: =IF(Input!N34=0,"",Input!N34) | O35: =IF(Input!E34=0,"",Input!E34)

Sheet CEO Dashboard

Sheet History
C2: #VALUE!
P3: =NOW() -> 46127.533
C6: Sr. No | D6: Bid Date | E6: Project Name | F6: Client | G6: Consultant | H6: Sector | I6: Estimated Value | J6: Contract Value | K6: Total Score | L6: Result (Won/Lost) | M6: Gross Margin % | N6: Main Competitor | O6: Loss Reason | P6: Notes
C7: {=_xlfn.SEQUENCE(COUNTA(E$7:E$1048576))} -> 1 | D7: =Input!K10 -> 44562 | E7: =Input!D10 -> Al Rimal | F7: =Input!O10 -> 1 | G7: =Input!Q10 -> AECOM | H7: =Input!P10 -> Gov | I7: =Input!G10 -> 1000000 | J7: ='CEO Input'!P8 -> 800000 | K7: =Input!AT10 -> 51 | L7: =Input!AY10 -> Rejected
